{"name": "test_getting_users_list", "status": "broken", "statusDetails": {"message": "pydantic.error_wrappers.ValidationError: 1 validation error for User\nname\n  value is not a valid integer (type=type_error.integer)", "trace": "get_users = <Response [200]>\n\n    def test_getting_users_list(get_users):\n    \n>       Response(get_users).asert_status_code(200).validate(User)\n\ntests\\users\\test_users.py:21: \n_ _ _ _ _ _ _ _ _ _ _ _ _ _ _ _ _ _ _ _ _ _ _ _ _ _ _ _ _ _ _ _ _ _ _ _ _ _ _ _ _ _ _ _ _ _ _ _ _ _ _ _ _ _ _ _ _ _ _ _ _ _ _ _ \nsrc\\base_classes\\response.py:16: in validate\n    schema.parse_obj(item)\npydantic\\main.py:521: in pydantic.main.BaseModel.parse_obj\n    ???\n_ _ _ _ _ _ _ _ _ _ _ _ _ _ _ _ _ _ _ _ _ _ _ _ _ _ _ _ _ _ _ _ _ _ _ _ _ _ _ _ _ _ _ _ _ _ _ _ _ _ _ _ _ _ _ _ _ _ _ _ _ _ _ _ \n\n>   ???\nE   pydantic.error_wrappers.ValidationError: 1 validation error for User\nE   name\nE     value is not a valid integer (type=type_error.integer)\n\npydantic\\main.py:341: ValidationError"}, "start": 1655719257527, "stop": 1655719257528, "uuid": "ea19d86f-6942-45c9-99b8-83d8a92ca74c", "historyId": "a8cd091c167665d3ed0d6c85ad20edfc", "testCaseId": "f3a35b35911a2442325e664a2ed974e0", "fullName": "tests.users.test_users#test_getting_users_list", "labels": [{"name": "parentSuite", "value": "tests.users"}, {"name": "suite", "value": "test_users"}, {"name": "host", "value": "LAPTOP-7I0MTG2N"}, {"name": "thread", "value": "19568-MainThread"}, {"name": "framework", "value": "pytest"}, {"name": "language", "value": "cpython3"}, {"name": "package", "value": "tests.users.test_users"}]}